<?xml version="1.0" encoding="UTF-8"?>
<robot xmlns:xacro="http://www.ros.org/wiki/xacro">

	<xacro:include filename="00-wheels_properties.xacro" />

	<xacro:macro name="wheel" params="name parent reflect reflect_y">

		<link name="${name}_wheel">
			<inertial>
				<!-- based on thick-walled cylinder -->
				<origin xyz="0 ${reflect*wheel_length/2} 0" rpy="${M_PI/2} 0 0" />
				<mass value="1.24" />
				<inertia ixx="${wheel_Ixx_Iyy}" iyy="${wheel_Ixx_Iyy}"  izz="${wheel_Izz}" ixy="0.0" ixz="0.0" iyz="0.0" />
			</inertial>
			<visual>
				<xacro:if value="${reflect == -1}">
					<origin rpy="0 0 ${M_PI}" />
				</xacro:if>
				<geometry>
					<mesh filename="package://earth_rover_description/meshes/wheel.dae" />
				</geometry>
				<material name="black" />
			</visual>
			<collision>
				<origin xyz="0 ${reflect*wheel_length/2} 0" rpy="${M_PI/2} 0 0" />
				<geometry>
					<cylinder radius="${wheel_radius}" length="${wheel_length}" />
				</geometry>
			</collision>
		</link>

		<gazebo reference="${name}_wheel">
			<material>Gazebo/DarkGrey</material>
		</gazebo>

		<!-- Wheel Transmition & Joints -->
		<transmission name="${name}_wheel_transmission">
			<type>transmission_interface/SimpleTransmission</type>
			<actuator name="${name}_wheel_motor" />
			<joint name="${name}_wheel_joint">
				<hardwareInterface>hardware_interface/VelocityJointInterface</hardwareInterface>
			</joint>
		</transmission>

		<joint name="${name}_wheel_joint" type="continuous">
			<parent link="${name}_ankle" />
			<child link="${name}_wheel" />
			<axis xyz="0 1 0" />
			<origin xyz="0 ${reflect*wheel_offset_y} ${wheel_offset_z}" />
		</joint>

	</xacro:macro>
</robot>
